<?xml version="1.0" ?>
<!-- =================================================================================== -->
<!-- |    This document was autogenerated by xacro from urdf\biped.xacro.temp          | -->
<!-- |    EDITING THIS FILE BY HAND IS NOT RECOMMENDED                                 | -->
<!-- =================================================================================== -->
<robot xmlns:xacro="http://www.ros.org/wiki/xacro" name="biped">
  <material name="silver">
    <color rgba="0.700 0.700 0.700 1.000"/>
  </material>
  <transmission name="Revolute 1_tran">
    <type>transmission_interface/SimpleTransmission</type>
    <joint name="Revolute 1">
      <hardwareInterface>hardware_interface/EffortJointInterface</hardwareInterface>
    </joint>
    <actuator name="Revolute 1_actr">
      <hardwareInterface>hardware_interface/EffortJointInterface</hardwareInterface>
      <mechanicalReduction>1</mechanicalReduction>
    </actuator>
  </transmission>
  <transmission name="Revolute 2_tran">
    <type>transmission_interface/SimpleTransmission</type>
    <joint name="Revolute 2">
      <hardwareInterface>hardware_interface/EffortJointInterface</hardwareInterface>
    </joint>
    <actuator name="Revolute 2_actr">
      <hardwareInterface>hardware_interface/EffortJointInterface</hardwareInterface>
      <mechanicalReduction>1</mechanicalReduction>
    </actuator>
  </transmission>
  <transmission name="Revolute 3_tran">
    <type>transmission_interface/SimpleTransmission</type>
    <joint name="Revolute 3">
      <hardwareInterface>hardware_interface/EffortJointInterface</hardwareInterface>
    </joint>
    <actuator name="Revolute 3_actr">
      <hardwareInterface>hardware_interface/EffortJointInterface</hardwareInterface>
      <mechanicalReduction>1</mechanicalReduction>
    </actuator>
  </transmission>
  <transmission name="Revolute 4_tran">
    <type>transmission_interface/SimpleTransmission</type>
    <joint name="Revolute 4">
      <hardwareInterface>hardware_interface/EffortJointInterface</hardwareInterface>
    </joint>
    <actuator name="Revolute 4_actr">
      <hardwareInterface>hardware_interface/EffortJointInterface</hardwareInterface>
      <mechanicalReduction>1</mechanicalReduction>
    </actuator>
  </transmission>
  <transmission name="Revolute 5_tran">
    <type>transmission_interface/SimpleTransmission</type>
    <joint name="Revolute 5">
      <hardwareInterface>hardware_interface/EffortJointInterface</hardwareInterface>
    </joint>
    <actuator name="Revolute 5_actr">
      <hardwareInterface>hardware_interface/EffortJointInterface</hardwareInterface>
      <mechanicalReduction>1</mechanicalReduction>
    </actuator>
  </transmission>
  <transmission name="Revolute 6_tran">
    <type>transmission_interface/SimpleTransmission</type>
    <joint name="Revolute 6">
      <hardwareInterface>hardware_interface/EffortJointInterface</hardwareInterface>
    </joint>
    <actuator name="Revolute 6_actr">
      <hardwareInterface>hardware_interface/EffortJointInterface</hardwareInterface>
      <mechanicalReduction>1</mechanicalReduction>
    </actuator>
  </transmission>
  <transmission name="Revolute 7_tran">
    <type>transmission_interface/SimpleTransmission</type>
    <joint name="Revolute 7">
      <hardwareInterface>hardware_interface/EffortJointInterface</hardwareInterface>
    </joint>
    <actuator name="Revolute 7_actr">
      <hardwareInterface>hardware_interface/EffortJointInterface</hardwareInterface>
      <mechanicalReduction>1</mechanicalReduction>
    </actuator>
  </transmission>
  <transmission name="Revolute 8_tran">
    <type>transmission_interface/SimpleTransmission</type>
    <joint name="Revolute 8">
      <hardwareInterface>hardware_interface/EffortJointInterface</hardwareInterface>
    </joint>
    <actuator name="Revolute 8_actr">
      <hardwareInterface>hardware_interface/EffortJointInterface</hardwareInterface>
      <mechanicalReduction>1</mechanicalReduction>
    </actuator>
  </transmission>
  <transmission name="Revolute 12_tran">
    <type>transmission_interface/SimpleTransmission</type>
    <joint name="Revolute 12">
      <hardwareInterface>hardware_interface/EffortJointInterface</hardwareInterface>
    </joint>
    <actuator name="Revolute 12_actr">
      <hardwareInterface>hardware_interface/EffortJointInterface</hardwareInterface>
      <mechanicalReduction>1</mechanicalReduction>
    </actuator>
  </transmission>
  <transmission name="Revolute 13_tran">
    <type>transmission_interface/SimpleTransmission</type>
    <joint name="Revolute 13">
      <hardwareInterface>hardware_interface/EffortJointInterface</hardwareInterface>
    </joint>
    <actuator name="Revolute 13_actr">
      <hardwareInterface>hardware_interface/EffortJointInterface</hardwareInterface>
      <mechanicalReduction>1</mechanicalReduction>
    </actuator>
  </transmission>
  <transmission name="Slider 14_tran">
    <type>transmission_interface/SimpleTransmission</type>
    <joint name="Slider 14">
      <hardwareInterface>hardware_interface/EffortJointInterface</hardwareInterface>
    </joint>
    <actuator name="Slider 14_actr">
      <hardwareInterface>hardware_interface/EffortJointInterface</hardwareInterface>
      <mechanicalReduction>1</mechanicalReduction>
    </actuator>
  </transmission>
  <transmission name="Revolute 15_tran">
    <type>transmission_interface/SimpleTransmission</type>
    <joint name="Revolute 15">
      <hardwareInterface>hardware_interface/EffortJointInterface</hardwareInterface>
    </joint>
    <actuator name="Revolute 15_actr">
      <hardwareInterface>hardware_interface/EffortJointInterface</hardwareInterface>
      <mechanicalReduction>1</mechanicalReduction>
    </actuator>
  </transmission>
  <!-- omitted .gazebo include -->
  <link name="base_link">
    <inertial>
      <origin xyz="-4.0314630566490926e-19 -2.311756942495181e-18 0.0026594776595595215" rpy="0 0 0"/>
      <mass value="0.0007331653384976692"/>
      <inertia ixx="0.0" iyy="0.0" izz="0.0" ixy="-0.0" iyz="-0.0" ixz="-0.0"/>
    </inertial>
    <visual>
      <origin xyz="0 0 0" rpy="0 0 0"/>
      <geometry>
        <mesh filename="package://biped_description/meshes/base_link.stl" scale="0.001 0.001 0.001"/>
      </geometry>
      <material name="silver"/>
    </visual>
    <collision>
      <origin xyz="0 0 0" rpy="0 0 0"/>
      <geometry>
        <mesh filename="package://biped_description/meshes/base_link.stl" scale="0.001 0.001 0.001"/>
      </geometry>
    </collision>
  </link>
  <link name="l_hip_1">
    <inertial>
      <origin xyz="-0.0019999999999999987 -7.264315754831885e-11 -0.0021500000223517394" rpy="0 0 0"/>
      <mass value="8.634107252961229e-05"/>
      <inertia ixx="0.0" iyy="0.0" izz="0.0" ixy="-0.0" iyz="-0.0" ixz="0.0"/>
    </inertial>
    <visual>
      <origin xyz="-0.002 -0.00325 -0.001" rpy="0 0 0"/>
      <geometry>
        <mesh filename="package://biped_description/meshes/l_hip_1.stl" scale="0.001 0.001 0.001"/>
      </geometry>
      <material name="silver"/>
    </visual>
    <collision>
      <origin xyz="-0.002 -0.00325 -0.001" rpy="0 0 0"/>
      <geometry>
        <mesh filename="package://biped_description/meshes/l_hip_1.stl" scale="0.001 0.001 0.001"/>
      </geometry>
    </collision>
  </link>
  <link name="r_hip_1">
    <inertial>
      <origin xyz="-0.0020000000000000026 7.264315277782929e-11 -0.0021500000223517394" rpy="0 0 0"/>
      <mass value="8.634107252961229e-05"/>
      <inertia ixx="0.0" iyy="0.0" izz="0.0" ixy="-0.0" iyz="-0.0" ixz="0.0"/>
    </inertial>
    <visual>
      <origin xyz="-0.002 0.00325 -0.001" rpy="0 0 0"/>
      <geometry>
        <mesh filename="package://biped_description/meshes/r_hip_1.stl" scale="0.001 0.001 0.001"/>
      </geometry>
      <material name="silver"/>
    </visual>
    <collision>
      <origin xyz="-0.002 0.00325 -0.001" rpy="0 0 0"/>
      <geometry>
        <mesh filename="package://biped_description/meshes/r_hip_1.stl" scale="0.001 0.001 0.001"/>
      </geometry>
    </collision>
  </link>
  <link name="l_thigh_1">
    <inertial>
      <origin xyz="-2.2352835971073405e-11 -0.0020000000726431533 -0.002999999955296517" rpy="0 0 0"/>
      <mass value="0.0005023753384976689"/>
      <inertia ixx="0.0" iyy="0.0" izz="0.0" ixy="-0.0" iyz="-0.0" ixz="0.0"/>
    </inertial>
    <visual>
      <origin xyz="-0.0 -0.00525 0.0033" rpy="0 0 0"/>
      <geometry>
        <mesh filename="package://biped_description/meshes/l_thigh_1.stl" scale="0.001 0.001 0.001"/>
      </geometry>
      <material name="silver"/>
    </visual>
    <collision>
      <origin xyz="-0.0 -0.00525 0.0033" rpy="0 0 0"/>
      <geometry>
        <mesh filename="package://biped_description/meshes/l_thigh_1.stl" scale="0.001 0.001 0.001"/>
      </geometry>
    </collision>
  </link>
  <link name="r_thigh_1">
    <inertial>
      <origin xyz="-2.2352838191519453e-11 0.0020000000726431494 -0.002999999955296517" rpy="0 0 0"/>
      <mass value="0.0005023753384976689"/>
      <inertia ixx="0.0" iyy="0.0" izz="0.0" ixy="-0.0" iyz="0.0" ixz="0.0"/>
    </inertial>
    <visual>
      <origin xyz="0.0 0.00525 0.0033" rpy="0 0 0"/>
      <geometry>
        <mesh filename="package://biped_description/meshes/r_thigh_1.stl" scale="0.001 0.001 0.001"/>
      </geometry>
      <material name="silver"/>
    </visual>
    <collision>
      <origin xyz="0.0 0.00525 0.0033" rpy="0 0 0"/>
      <geometry>
        <mesh filename="package://biped_description/meshes/r_thigh_1.stl" scale="0.001 0.001 0.001"/>
      </geometry>
    </collision>
  </link>
  <link name="l_calf_1">
    <inertial>
      <origin xyz="3.059388659076845e-11 -0.002000000072643155 -0.003914288283714446" rpy="0 0 0"/>
      <mass value="0.00029110830222198907"/>
      <inertia ixx="0.0" iyy="0.0" izz="0.0" ixy="-0.0" iyz="0.0" ixz="0.0"/>
    </inertial>
    <visual>
      <origin xyz="-0.0 -0.00525 0.0093" rpy="0 0 0"/>
      <geometry>
        <mesh filename="package://biped_description/meshes/l_calf_1.stl" scale="0.001 0.001 0.001"/>
      </geometry>
      <material name="silver"/>
    </visual>
    <collision>
      <origin xyz="-0.0 -0.00525 0.0093" rpy="0 0 0"/>
      <geometry>
        <mesh filename="package://biped_description/meshes/l_calf_1.stl" scale="0.001 0.001 0.001"/>
      </geometry>
    </collision>
  </link>
  <link name="r_calf_1">
    <inertial>
      <origin xyz="3.059388173354271e-11 0.0020000000726431515 -0.003914288283714446" rpy="0 0 0"/>
      <mass value="0.00029110830222198907"/>
      <inertia ixx="0.0" iyy="0.0" izz="0.0" ixy="0.0" iyz="0.0" ixz="0.0"/>
    </inertial>
    <visual>
      <origin xyz="0.0 0.00525 0.0093" rpy="0 0 0"/>
      <geometry>
        <mesh filename="package://biped_description/meshes/r_calf_1.stl" scale="0.001 0.001 0.001"/>
      </geometry>
      <material name="silver"/>
    </visual>
    <collision>
      <origin xyz="0.0 0.00525 0.0093" rpy="0 0 0"/>
      <geometry>
        <mesh filename="package://biped_description/meshes/r_calf_1.stl" scale="0.001 0.001 0.001"/>
      </geometry>
    </collision>
  </link>
  <link name="l_ankle_1">
    <inertial>
      <origin xyz="2.2351747620277e-11 -0.002000000072643157 -0.002149999865889549" rpy="0 0 0"/>
      <mass value="8.634107252961244e-05"/>
      <inertia ixx="0.0" iyy="0.0" izz="0.0" ixy="-0.0" iyz="0.0" ixz="-0.0"/>
    </inertial>
    <visual>
      <origin xyz="-0.0 -0.00525 0.0146" rpy="0 0 0"/>
      <geometry>
        <mesh filename="package://biped_description/meshes/l_ankle_1.stl" scale="0.001 0.001 0.001"/>
      </geometry>
      <material name="silver"/>
    </visual>
    <collision>
      <origin xyz="-0.0 -0.00525 0.0146" rpy="0 0 0"/>
      <geometry>
        <mesh filename="package://biped_description/meshes/l_ankle_1.stl" scale="0.001 0.001 0.001"/>
      </geometry>
    </collision>
  </link>
  <link name="r_ankle_1">
    <inertial>
      <origin xyz="2.2351739736024254e-11 0.002000000072643144 -0.0021499998882412875" rpy="0 0 0"/>
      <mass value="8.634107252961244e-05"/>
      <inertia ixx="0.0" iyy="0.0" izz="0.0" ixy="-0.0" iyz="0.0" ixz="0.0"/>
    </inertial>
    <visual>
      <origin xyz="-0.0 0.00525 0.0146" rpy="0 0 0"/>
      <geometry>
        <mesh filename="package://biped_description/meshes/r_ankle_1.stl" scale="0.001 0.001 0.001"/>
      </geometry>
      <material name="silver"/>
    </visual>
    <collision>
      <origin xyz="-0.0 0.00525 0.0146" rpy="0 0 0"/>
      <geometry>
        <mesh filename="package://biped_description/meshes/r_ankle_1.stl" scale="0.001 0.001 0.001"/>
      </geometry>
    </collision>
  </link>
  <link name="l_foot_1">
    <inertial>
      <origin xyz="-0.001999999977648251 0.0012260273246171237 -0.0005198628795881795" rpy="0 0 0"/>
      <mass value="0.00045844"/>
      <inertia ixx="0.0" iyy="0.0" izz="0.0" ixy="0.0" iyz="0.0" ixz="0.0"/>
    </inertial>
    <visual>
      <origin xyz="-0.002 -0.00325 0.0189" rpy="0 0 0"/>
      <geometry>
        <mesh filename="package://biped_description/meshes/l_foot_1.stl" scale="0.001 0.001 0.001"/>
      </geometry>
      <material name="silver"/>
    </visual>
    <collision>
      <origin xyz="-0.002 -0.00325 0.0189" rpy="0 0 0"/>
      <geometry>
        <mesh filename="package://biped_description/meshes/l_foot_1.stl" scale="0.001 0.001 0.001"/>
      </geometry>
    </collision>
  </link>
  <link name="r_foot_1">
    <inertial>
      <origin xyz="-0.00199999997764826 -0.001226060268704573 -0.0005198768851741135" rpy="0 0 0"/>
      <mass value="0.00045842766924883465"/>
      <inertia ixx="0.0" iyy="0.0" izz="0.0" ixy="-0.0" iyz="-0.0" ixz="-0.0"/>
    </inertial>
    <visual>
      <origin xyz="-0.002 0.00325 0.0189" rpy="0 0 0"/>
      <geometry>
        <mesh filename="package://biped_description/meshes/r_foot_1.stl" scale="0.001 0.001 0.001"/>
      </geometry>
      <material name="silver"/>
    </visual>
    <collision>
      <origin xyz="-0.002 0.00325 0.0189" rpy="0 0 0"/>
      <geometry>
        <mesh filename="package://biped_description/meshes/r_foot_1.stl" scale="0.001 0.001 0.001"/>
      </geometry>
    </collision>
  </link>
  <link name="sacrum_1">
    <inertial>
      <origin xyz="-5.322339130313942e-12 -4.923167429282671e-12 0.0020426460827791997" rpy="0 0 0"/>
      <mass value="0.0001318676695997575"/>
      <inertia ixx="0.0" iyy="0.0" izz="0.0" ixy="-0.0" iyz="0.0" ixz="0.0"/>
    </inertial>
    <visual>
      <origin xyz="0.0 -0.0 -0.0043" rpy="0 0 0"/>
      <geometry>
        <mesh filename="package://biped_description/meshes/sacrum_1.stl" scale="0.001 0.001 0.001"/>
      </geometry>
      <material name="silver"/>
    </visual>
    <collision>
      <origin xyz="0.0 -0.0 -0.0043" rpy="0 0 0"/>
      <geometry>
        <mesh filename="package://biped_description/meshes/sacrum_1.stl" scale="0.001 0.001 0.001"/>
      </geometry>
    </collision>
  </link>
  <link name="back_1">
    <inertial>
      <origin xyz="-4.243683698498517e-11 -0.0016999999999999988 0.004605215490604516" rpy="0 0 0"/>
      <mass value="0.0027553261785723494"/>
      <inertia ixx="0.0" iyy="0.0" izz="0.0" ixy="0.0" iyz="0.0" ixz="0.0"/>
    </inertial>
    <visual>
      <origin xyz="0.0 -0.0017 -0.0071" rpy="0 0 0"/>
      <geometry>
        <mesh filename="package://biped_description/meshes/back_1.stl" scale="0.001 0.001 0.001"/>
      </geometry>
      <material name="silver"/>
    </visual>
    <collision>
      <origin xyz="0.0 -0.0017 -0.0071" rpy="0 0 0"/>
      <geometry>
        <mesh filename="package://biped_description/meshes/back_1.stl" scale="0.001 0.001 0.001"/>
      </geometry>
    </collision>
  </link>
  <joint name="Revolute 1" type="revolute">
    <origin xyz="0.002 0.00325 0.001" rpy="0 0 0"/>
    <parent link="base_link"/>
    <child link="l_hip_1"/>
    <axis xyz="1.0 -0.0 0.0"/>
    <limit upper="1.396263" lower="-0.872665" effort="100" velocity="100"/>
  </joint>
  <joint name="Revolute 2" type="revolute">
    <origin xyz="0.002 -0.00325 0.001" rpy="0 0 0"/>
    <parent link="base_link"/>
    <child link="r_hip_1"/>
    <axis xyz="1.0 -0.0 0.0"/>
    <limit upper="0.872665" lower="-1.396263" effort="100" velocity="100"/>
  </joint>
  <joint name="Revolute 3" type="revolute">
    <origin xyz="-0.002 0.002 -0.0043" rpy="0 0 0"/>
    <parent link="l_hip_1"/>
    <child link="l_thigh_1"/>
    <axis xyz="-0.0 -1.0 0.0"/>
    <limit upper="1.570796" lower="-1.570796" effort="100" velocity="100"/>
  </joint>
  <joint name="Revolute 4" type="revolute">
    <origin xyz="-0.002 -0.002 -0.0043" rpy="0 0 0"/>
    <parent link="r_hip_1"/>
    <child link="r_thigh_1"/>
    <axis xyz="0.0 1.0 0.0"/>
    <limit upper="1.570796" lower="-1.570796" effort="100" velocity="100"/>
  </joint>
  <joint name="Revolute 5" type="revolute">
    <origin xyz="0.0 0.0 -0.006" rpy="0 0 0"/>
    <parent link="l_thigh_1"/>
    <child link="l_calf_1"/>
    <axis xyz="-0.0 1.0 0.0"/>
    <limit upper="1.570796" lower="-1.570796" effort="100" velocity="100"/>
  </joint>
  <joint name="Revolute 6" type="revolute">
    <origin xyz="0.0 0.0 -0.006" rpy="0 0 0"/>
    <parent link="r_thigh_1"/>
    <child link="r_calf_1"/>
    <axis xyz="-0.0 -1.0 0.0"/>
    <limit upper="1.570796" lower="-1.570796" effort="100" velocity="100"/>
  </joint>
  <joint name="Revolute 7" type="revolute">
    <origin xyz="0.0 0.0 -0.0053" rpy="0 0 0"/>
    <parent link="l_calf_1"/>
    <child link="l_ankle_1"/>
    <axis xyz="0.0 1.0 0.0"/>
    <limit upper="1.570796" lower="-1.570796" effort="100" velocity="100"/>
  </joint>
  <joint name="Revolute 8" type="revolute">
    <origin xyz="0.0 0.0 -0.0053" rpy="0 0 0"/>
    <parent link="r_calf_1"/>
    <child link="r_ankle_1"/>
    <axis xyz="0.0 -1.0 0.0"/>
    <limit upper="1.570796" lower="-1.570796" effort="100" velocity="100"/>
  </joint>
  <joint name="Revolute 12" type="revolute">
    <origin xyz="0.002 -0.002 -0.0043" rpy="0 0 0"/>
    <parent link="l_ankle_1"/>
    <child link="l_foot_1"/>
    <axis xyz="-1.0 -0.0 0.0"/>
    <limit upper="0.698132" lower="-0.349066" effort="100" velocity="100"/>
  </joint>
  <joint name="Revolute 13" type="revolute">
    <origin xyz="0.002 0.002 -0.0043" rpy="0 0 0"/>
    <parent link="r_ankle_1"/>
    <child link="r_foot_1"/>
    <axis xyz="-1.0 0.0 0.0"/>
    <limit upper="0.349066" lower="-0.698132" effort="100" velocity="100"/>
  </joint>
  <joint name="Slider 14" type="prismatic">
    <origin xyz="0.0 0.0 0.0043" rpy="0 0 0"/>
    <parent link="base_link"/>
    <child link="sacrum_1"/>
    <axis xyz="-0.0 -1.0 0.0"/>
    <limit upper="0.009" lower="-0.009" effort="100" velocity="100"/>
  </joint>
  <joint name="Revolute 15" type="revolute">
    <origin xyz="0.0 0.0017 0.0028" rpy="0 0 0"/>
    <parent link="sacrum_1"/>
    <child link="back_1"/>
    <axis xyz="-0.0 -1.0 0.0"/>
    <limit upper="1.570796" lower="-1.570796" effort="100" velocity="100"/>
  </joint>
</robot>
